Workbook

Sheet Tableur_plat_Erreurs
A2: Intitulés différents dans TEND (uniquement)
A3: Bioénergies | B3: Biomasse | C3: Biogaz issu de Cultures intermédiaires méthanisées | D3: TWh | E3: TEND | H3: Cultures intermédiaires méthanisées
A4: Bioénergies | B4: Biomasse | C4: Biogaz issu de déchets alimentaires | D4: TWh | E4: TEND | H4: Déchets alimentaires
A5: Bioénergies | B5: Biomasse | C5: Biogaz issu de déjections d'élevage méthanisées | D5: TWh | E5: TEND | H5: Déjections d'élevage méthanisées
A6: Bioénergies | B6: Biomasse | C6: Biogaz issu de Herbe et cultures fourragères méthanisées | D6: TWh | E6: TEND | H6: Herbe et cultures fourragères méthanisées
A7: Bioénergies | B7: Biomasse | C7: Biogaz issu de Résidus de culture méthanisés | D7: TWh | E7: TEND | H7: Résidus de culture méthanisés
A8: Bioénergies | B8: Biomasse liquide | C8: Biocarburants 2nde generation | D8: TWh | E8: TEND | G8: Biomasse
A9: Bioénergies | B9: Biomasse liquide | C9: Biodiesel | D9: TWh | E9: TEND | G9: Biomasse
A10: Bioénergies | B10: Biomasse liquide | C10: Biogazole d'algues | D10: TWh | E10: TEND | G10: Biomasse
A11: Bioénergies | B11: Biomasse liquide | C11: Ethanol | D11: TWh | E11: TEND | G11: Biomasse
A12: Bioénergies | B12: Biomasse liquide | C12: Ethanol d'algues | D12: TWh | E12: TEND | G12: Biomasse
A13: Indicateurs agro-environnementaux | B13: Consommation d'eau | C13: Consommation d'eau pour l'irrigation du maïs | D13: M m3 | E13: TEND | H13: maïs
A14: Indicateurs agro-environnementaux | B14: Surface irriguée | C14: Surface irriguée de céréales hors maïs | D14: kha | E14: TEND | H14: céréales hors maïs
A15: Indicateurs agro-environnementaux | B15: Surface irriguée | C15: Surface irriguée de légumes, fruits | D15: kha | E15: TEND | H15: légumes, fruits
A16: Indicateurs agro-environnementaux | B16: Surface irriguée | C16: Surface irriguée de maïs | D16: kha | E16: TEND | H16: maïs
A18: Intitulé modifié
A19: Indicateurs agro-environnementaux | C19: Linéaire de haies nouvelles -> Linéraire de haies | D19: milliers de km | E19: S1
A20: Indicateurs agro-environnementaux | C20: Linéaire de haies nouvelles | D20: milliers de km | E20: S2
A21: Indicateurs agro-environnementaux | C21: Linéaire de haies nouvelles | D21: milliers de km | E21: S3
A22: Indicateurs agro-environnementaux | C22: Linéaire de haies nouvelles | D22: milliers de km | E22: S4
A23: Indicateurs agro-environnementaux | C23: Linéaire de haies nouvelles | D23: milliers de km | E23: TEND
A25: Ligne supprimée
A26: Indicateurs agro-environnementaux | C26: Surfaces en cultures intermédiaires | D26: kha | E26: S1
A27: Indicateurs agro-environnementaux | C27: Surfaces en cultures intermédiaires | D27: kha | E27: S2
A28: Indicateurs agro-environnementaux | C28: Surfaces en cultures intermédiaires | D28: kha | E28: S3
A29: Indicateurs agro-environnementaux | C29: Surfaces en cultures intermédiaires | D29: kha | E29: S4
A30: Indicateurs agro-environnementaux | C30: Surfaces en cultures intermédiaires | D30: kha | E30: TEND

Sheet ADEME
A1: Catégorie | B1: Sous-catégorie | C1: Variable | D1: Unité | E1: Scénario | F1: 2020 | G1: 2025 | H1: 2030 | I1: 2035 | J1: 2040 | K1: 2045 | L1: 2050 | M1: Intitule_developpe | N1: Correspondance
A2: Alimentation Humaine | B2: Approvisionnement | C2: Boissons alcooliques | D2: kt | E2: TEND | F2: 6204.445 | G2: 6265.7309 | H2: 6335.1426 | I2: 6397.1438 | J2: 6441.5308 | K2: 6460.896 | L2: 6452.1059 | M2: =A2&"-"&B2&"-"&C2&"-"&D2&"-"&E2 -> Alimentation Humaine-Approvisionnement-Boissons alcooliques-kt-TEND | N2: =MATCH(M2,'[1]Données Agriculture'!$M:$M,FALSE) -> 2
A3: Alimentation Humaine | B3: Approvisionnement | C3: Café thé cacao | D3: kt | E3: TEND | F3: 657.84814 | G3: 647.71434 | H3: 609.33069 | I3: 553.35109 | J3: 495.84164 | K3: 452.92334 | L3: 436.2066 | M3: =A3&"-"&B3&"-"&C3&"-"&D3&"-"&E3 -> Alimentation Humaine-Approvisionnement-Café thé cacao-kt-TEND | N3: =MATCH(M3,'[1]Données Agriculture'!$M:$M,FALSE) -> 7
A4: Alimentation Humaine | B4: Approvisionnement | C4: Céréales | D4: kt | E4: TEND | F4: 8121.3816 | G4: 8180.0485 | H4: 8211.5309 | I4: 8211.2675 | J4: 8188.1212 | K4: 8154.5687 | L4: 8122.3487 | M4: =A4&"-"&B4&"-"&C4&"-"&D4&"-"&E4 -> Alimentation Humaine-Approvisionnement-Céréales-kt-TEND | N4: =MATCH(M4,'[1]Données Agriculture'!$M:$M,FALSE) -> 12
A5: Alimentation Humaine | B5: Approvisionnement | C5: Coquillages et crustacés | D5: kt | E5: TEND | F5: 624.82049 | G5: 632.75999 | H5: 644.63506 | I5: 657.61485 | J5: 668.85015 | K5: 675.73313 | L5: 676.58924 | M5: =A5&"-"&B5&"-"&C5&"-"&D5&"-"&E5 -> Alimentation Humaine-Approvisionnement-Coquillages et crustacés-kt-TEND | N5: =MATCH(M5,'[1]Données Agriculture'!$M:$M,FALSE) -> 17
A6: Alimentation Humaine | B6: Approvisionnement | C6: Fruits | D6: kt | E6: TEND | F6: 6659.2392 | G6: 6915.6702 | H6: 7513.4878 | I6: 8293.16 | J6: 9047.1251 | K6: 9576.55 | L6: 9745.199 | M6: =A6&"-"&B6&"-"&C6&"-"&D6&"-"&E6 -> Alimentation Humaine-Approvisionnement-Fruits-kt-TEND | N6: =MATCH(M6,'[1]Données Agriculture'!$M:$M,FALSE) -> 22
A7: Alimentation Humaine | B7: Approvisionnement | C7: Fruits coque | D7: kt | E7: TEND | F7: 523.9601 | G7: 552.0603 | H7: 621.3136 | I7: 714.05653 | J7: 805.80464 | K7: 871.67507 | L7: 893.62475 | M7: =A7&"-"&B7&"-"&C7&"-"&D7&"-"&E7 -> Alimentation Humaine-Approvisionnement-Fruits coque-kt-TEND | N7: =MATCH(M7,'[1]Données Agriculture'!$M:$M,FALSE) -> 27
A8: Alimentation Humaine | B8: Approvisionnement | C8: Lait et beurre | D8: kt | E8: TEND | F8: 15287.544 | G8: 15383.032 | H8: 15400.97 | I8: 15343.436 | J8: 15242.514 | K8: 15137.497 | L8: 15062.06 | M8: =A8&"-"&B8&"-"&C8&"-"&D8&"-"&E8 -> Alimentation Humaine-Approvisionnement-Lait et beurre-kt-TEND | N8: =MATCH(M8,'[1]Données Agriculture'!$M:$M,FALSE) -> 32
A9: Alimentation Humaine | B9: Approvisionnement | C9: Légumes | D9: kt | E9: TEND | F9: 7002.9432 | G9: 7122.3179 | H9: 7338.3459 | I9: 7595.674 | J9: 7831.0106 | K9: 7986.0508 | L9: 8022.7097 | M9: =A9&"-"&B9&"-"&C9&"-"&D9&"-"&E9 -> Alimentation Humaine-Approvisionnement-Légumes-kt-TEND | N9: =MATCH(M9,'[1]Données Agriculture'!$M:$M,FALSE) -> 37
A10: Alimentation Humaine | B10: Approvisionnement | C10: Légumineuses | D10: kt | E10: TEND | F10: 99.691524 | G10: 109.75543 | H10: 135.9724 | I10: 171.60951 | J10: 207.14699 | K10: 232.87053 | L10: 241.70488 | M10: =A10&"-"&B10&"-"&C10&"-"&D10&"-"&E10 -> Alimentation Humaine-Approvisionnement-Légumineuses-kt-TEND | N10: =MATCH(M10,'[1]Données Agriculture'!$M:$M,FALSE) -> 42
A11: Alimentation Humaine | B11: Approvisionnement | C11: Œufs | D11: kt | E11: TEND | F11: 831.7287 | G11: 839.65653 | H11: 848.18872 | I11: 855.48865 | J11: 860.48592 | K11: 862.42751 | L11: 861.02751 | M11: =A11&"-"&B11&"-"&C11&"-"&D11&"-"&E11 -> Alimentation Humaine-Approvisionnement-Œufs-kt-TEND | N11: =MATCH(M11,'[1]Données Agriculture'!$M:$M,FALSE) -> 47
A12: Alimentation Humaine | B12: Approvisionnement | C12: Plantes oléifères et huiles | D12: kt | E12: TEND | F12: 984.3572 | G12: 1016.8266 | H12: 1090.755 | I12: 1187.4853 | J12: 1281.9605 | K12: 1348.8864 | L12: 1370.0565 | M12: =A12&"-"&B12&"-"&C12&"-"&D12&"-"&E12 -> Alimentation Humaine-Approvisionnement-Plantes oléifères et huiles-kt-TEND | N12: =MATCH(M12,'[1]Données Agriculture'!$M:$M,FALSE) -> 52
A13: Alimentation Humaine | B13: Approvisionnement | C13: Poissons | D13: kt | E13: TEND | F13: 1488.8137 | G13: 1531.3091 | H13: 1624.5875 | I13: 1744.708 | J13: 1860.5779 | K13: 1941.6335 | L13: 1966.4255 | M13: =A13&"-"&B13&"-"&C13&"-"&D13&"-"&E13 -> Alimentation Humaine-Approvisionnement-Poissons-kt-TEND | N13: =MATCH(M13,'[1]Données Agriculture'!$M:$M,FALSE) -> 57
... A80: Bilan alimentation animale | B80: Surfaces allouées à l'alimentation animale | C80: Surfaces de prairies permanentes allouées aux productions animales | D80: kha | E80: TEND | F80: 10355.723 | G80: 9595.2087 | H80: 7404.4045 | I80: 4089.1785 | J80: 285.47193 | K80: -2913.3718 | L80: -4194.102 | M80: =A80&"-"&B80&"-"&C80&"-"&D80&"-"&E80 -> Bilan alimentation animale-Surfaces allouées à l'alimentation animale-Surfaces de prairies permanentes allouées aux productions animales-kha-TEND | N80: =MATCH(M80,'[1]Données Agriculture'!$M:$M,FALSE) -> 392
A81: Bilan azote | C81: Bilan d'azote total | D81: ktN | E81: TEND | F81: 5889.9078 | G81: 5882.5047 | H81: 5862.2789 | I81: 5834.65 | J81: 5807.0211 | K81: 5786.7954 | L81: 5779.3922 | M81: =A81&"-"&B81&"-"&C81&"-"&D81&"-"&E81 -> Bilan azote--Bilan d'azote total-ktN-TEND | N81: =MATCH(M81,'[1]Données Agriculture'!$M:$M,FALSE) -> 397
A82: Bilan azote | C82: Engrais minéraux | D82: ktN | E82: TEND | F82: 1742.05 | G82: 1698.2439 | H82: 1578.5632 | I82: 1415.0765 | J82: 1251.5898 | K82: 1131.9091 | L82: 1088.103 | M82: =A82&"-"&B82&"-"&C82&"-"&D82&"-"&E82 -> Bilan azote--Engrais minéraux-ktN-TEND | N82: =MATCH(M82,'[1]Données Agriculture'!$M:$M,FALSE) -> 402
A83: Bilan azote | C83: Exportations par les cultures | D83: ktN | E83: TEND | F83: -2959.319 | G83: -2979.6782 | H83: -3035.3007 | I83: -3111.2825 | J83: -3187.2643 | K83: -3242.8868 | L83: -3263.246 | M83: =A83&"-"&B83&"-"&C83&"-"&D83&"-"&E83 -> Bilan azote--Exportations par les cultures-ktN-TEND | N83: =MATCH(M83,'[1]Données Agriculture'!$M:$M,FALSE) -> 407
A84: Bilan azote | C84: Exportations par les fourrages et pâture | D84: ktN | E84: TEND | F84: -1228.122 | G84: -1231.907 | H84: -1242.2477 | I84: -1256.3735 | J84: -1270.4993 | K84: -1280.84 | L84: -1284.625 | M84: =A84&"-"&B84&"-"&C84&"-"&D84&"-"&E84 -> Bilan azote--Exportations par les fourrages et pâture-ktN-TEND | N84: =MATCH(M84,'[1]Données Agriculture'!$M:$M,FALSE) -> 412
A85: Bilan azote | C85: Fixation symbiotique | D85: ktN | E85: TEND | F85: 430.835 | G85: 454.08294 | H85: 517.5975 | I85: 604.36 | J85: 691.1225 | K85: 754.63706 | L85: 777.885 | M85: =A85&"-"&B85&"-"&C85&"-"&D85&"-"&E85 -> Bilan azote--Fixation symbiotique-ktN-TEND | N85: =MATCH(M85,'[1]Données Agriculture'!$M:$M,FALSE) -> 417
A86: Bilan azote | C86: Recyclage (engrais verts) | D86: ktN | E86: TEND | F86: 200.21188 | G86: 197.34442 | H86: 189.51035 | I86: 178.80881 | J86: 168.10727 | K86: 160.2732 | L86: 157.40574 | M86: =A86&"-"&B86&"-"&C86&"-"&D86&"-"&E86 -> Bilan azote--Recyclage (engrais verts)-ktN-TEND | N86: =MATCH(M86,'[1]Données Agriculture'!$M:$M,FALSE) -> 422
A87: Bilan azote | C87: Recyclage (épandage digestat) | D87: ktN | E87: TEND | F87: 109.184 | G87: 165.11665 | H87: 317.9275 | I87: 526.671 | J87: 735.4145 | K87: 888.22535 | L87: 944.158 | M87: =A87&"-"&B87&"-"&C87&"-"&D87&"-"&E87 -> Bilan azote--Recyclage (épandage digestat)-ktN-TEND | N87: =MATCH(M87,'[1]Données Agriculture'!$M:$M,FALSE) -> 427
A88: Bilan azote | C88: Recyclage (épandage fumier, lisier) | D88: ktN | E88: TEND | F88: 864.365 | G88: 823.30326 | H88: 711.1205 | I88: 557.876 | J88: 404.6315 | K88: 292.44874 | L88: 251.387 | M88: =A88&"-"&B88&"-"&C88&"-"&D88&"-"&E88 -> Bilan azote--Recyclage (épandage fumier, lisier)-ktN-TEND | N88: =MATCH(M88,'[1]Données Agriculture'!$M:$M,FALSE) -> 432
A89: Bilan azote | C89: Recyclage (redéposition atmosph., pâture, végétaux laissés au champ) | D89: ktN | E89: TEND | F89: 2543.2619 | G89: 2544.4136 | H89: 2547.5598 | I89: 2551.8577 | J89: 2556.1556 | K89: 2559.3019 | L89: 2560.4535 | M89: =A89&"-"&B89&"-"&C89&"-"&D89&"-"&E89 -> Bilan azote--Recyclage (redéposition atmosph., pâture, végétaux laissés au champ)-ktN-TEND | N89: =MATCH(M89,'[1]Données Agriculture'!$M:$M,FALSE) -> 437
A90: Bilan azote | C90: Solde au sol | D90: ktN | E90: TEND | F90: -968.517 | G90: -959.8321 | H90: -936.1045 | I90: -903.692 | J90: -871.2795 | K90: -847.5519 | L90: -838.867 | M90: =A90&"-"&B90&"-"&C90&"-"&D90&"-"&E90 -> Bilan azote--Solde au sol-ktN-TEND | N90: =MATCH(M90,'[1]Données Agriculture'!$M:$M,FALSE) -> 442
A91: Bilan azote | C91: Solde au sol (kg/ha) | D91: kg/ha | E91: TEND | F91: 34.291491 | G91: 34.063988 | H91: 33.436942 | I91: 32.567146 | J91: 31.681692 | K91: 31.023322 | L91: 30.780154 | M91: =A91&"-"&B91&"-"&C91&"-"&D91&"-"&E91 -> Bilan azote--Solde au sol (kg/ha)-kg/ha-TEND | N91: =MATCH(M91,'[1]Données Agriculture'!$M:$M,FALSE) -> 447
A92: Bilan azote | C92: Volatilisation | D92: ktN | E92: TEND | F92: -733.95 | G92: -711.08764 | H92: -648.6265 | I92: -563.303 | J92: -477.9795 | K92: -415.51836 | L92: -392.656 | M92: =A92&"-"&B92&"-"&C92&"-"&D92&"-"&E92 -> Bilan azote--Volatilisation-ktN-TEND | N92: =MATCH(M92,'[1]Données Agriculture'!$M:$M,FALSE) -> 452
A93: Bilan d'approvisionnement | B93: Alimentation animale | C93: Blé | D93: kt | E93: TEND | F93: 6514.9068 | G93: 6435.9425 | H93: 6129.5433 | I93: 5681.3813 | J93: 5220.1854 | K93: 4881.7481 | L93: 4769.9207 | M93: =A93&"-"&B93&"-"&C93&"-"&D93&"-"&E93 -> Bilan d'approvisionnement-Alimentation animale-Blé-kt-TEND | N93: =MATCH(M93,'[1]Données Agriculture'!$M:$M,FALSE) -> 457
A94: Bilan d'approvisionnement | B94: Alimentation animale | C94: Céréales | D94: kt | E94: TEND | F94: 17780.484 | G94: 17564.975 | H94: 16728.75 | I94: 15505.626 | J94: 14246.931 | K94: 13323.267 | L94: 13018.068 | M94: =A94&"-"&B94&"-"&C94&"-"&D94&"-"&E94 -> Bilan d'approvisionnement-Alimentation animale-Céréales-kt-TEND | N94: =MATCH(M94,'[1]Données Agriculture'!$M:$M,FALSE) -> 462
A95: Bilan d'approvisionnement | B95: Alimentation animale | C95: Fruits | D95: kt | E95: TEND | F95: 0 | G95: 0 | H95: 0 | I95: 0 | J95: 0 | K95: 0 | L95: 0 | M95: =A95&"-"&B95&"-"&C95&"-"&D95&"-"&E95 -> Bilan d'approvisionnement-Alimentation animale-Fruits-kt-TEND | N95: =MATCH(M95,'[1]Données Agriculture'!$M:$M,FALSE) -> 467
A96: Bilan d'approvisionnement | B96: Alimentation animale | C96: Lait | D96: kt | E96: TEND | F96: 1517.7457 | G96: 1499.3498 | H96: 1427.9694 | I96: 1323.5634 | J96: 1216.1208 | K96: 1137.2768 | L96: 1111.2249 | M96: =A96&"-"&B96&"-"&C96&"-"&D96&"-"&E96 -> Bilan d'approvisionnement-Alimentation animale-Lait-kt-TEND | N96: =MATCH(M96,'[1]Données Agriculture'!$M:$M,FALSE) -> 472
A97: Bilan d'approvisionnement | B97: Alimentation animale | C97: Légumes | D97: kt | E97: TEND | F97: 14.877889 | G97: 14.69756 | H97: 13.997846 | I97: 12.974392 | J97: 11.921174 | K97: 11.148295 | L97: 10.892918 | M97: =A97&"-"&B97&"-"&C97&"-"&D97&"-"&E97 -> Bilan d'approvisionnement-Alimentation animale-Légumes-kt-TEND | N97: =MATCH(M97,'[1]Données Agriculture'!$M:$M,FALSE) -> 477
A98: Bilan d'approvisionnement | B98: Alimentation animale | C98: Viande | D98: kt | E98: TEND | F98: 0 | G98: 0 | H98: 0 | I98: 0 | J98: 0 | K98: 0 | L98: 0 | M98: =A98&"-"&B98&"-"&C98&"-"&D98&"-"&E98 -> Bilan d'approvisionnement-Alimentation animale-Viande-kt-TEND | N98: =MATCH(M98,'[1]Données Agriculture'!$M:$M,FALSE) -> 482
A99: Bilan d'approvisionnement | B99: Alimentation humaine | C99: Blé | D99: kt | E99: TEND | F99: 6519.7484 | G99: 6529.0738 | H99: 6450.6775 | I99: 6309.2149 | J99: 6150.7533 | K99: 6023.1026 | L99: 5961.9783 | M99: =A99&"-"&B99&"-"&C99&"-"&D99&"-"&E99 -> Bilan d'approvisionnement-Alimentation humaine-Blé-kt-TEND | N99: =MATCH(M99,'[1]Données Agriculture'!$M:$M,FALSE) -> 487
A100: Bilan d'approvisionnement | B100: Alimentation humaine | C100: Céréales | D100: kt | E100: TEND | F100: 8121.3816 | G100: 8180.0485 | H100: 8211.5309 | I100: 8211.2675 | J100: 8188.1212 | K100: 8154.5687 | L100: 8122.3487 | M100: =A100&"-"&B100&"-"&C100&"-"&D100&"-"&E100 -> Bilan d'approvisionnement-Alimentation humaine-Céréales-kt-TEND | N100: =MATCH(M100,'[1]Données Agriculture'!$M:$M,FALSE) -> 492
A101: Bilan d'approvisionnement | B101: Alimentation humaine | C101: Fruits | D101: kt | E101: TEND | F101: 6659.2392 | G101: 6915.6702 | H101: 7513.4878 | I101: 8293.16 | J101: 9047.1251 | K101: 9576.55 | L101: 9745.199 | M101: =A101&"-"&B101&"-"&C101&"-"&D101&"-"&E101 -> Bilan d'approvisionnement-Alimentation humaine-Fruits-kt-TEND | N101: =MATCH(M101,'[1]Données Agriculture'!$M:$M,FALSE) -> 497
A102: Bilan d'approvisionnement | B102: Alimentation humaine | C102: Lait | D102: kt | E102: TEND | F102: 15287.544 | G102: 15383.032 | H102: 15400.97 | I102: 15343.436 | J102: 15242.514 | K102: 15137.497 | L102: 15062.06 | M102: =A102&"-"&B102&"-"&C102&"-"&D102&"-"&E102 -> Bilan d'approvisionnement-Alimentation humaine-Lait-kt-TEND | N102: =MATCH(M102,'[1]Données Agriculture'!$M:$M,FALSE) -> 502
A103: Bilan d'approvisionnement | B103: Alimentation humaine | C103: Légumes | D103: kt | E103: TEND | F103: 7002.9432 | G103: 7122.3179 | H103: 7338.3459 | I103: 7595.674 | J103: 7831.0106 | K103: 7986.0508 | L103: 8022.7097 | M103: =A103&"-"&B103&"-"&C103&"-"&D103&"-"&E103 -> Bilan d'approvisionnement-Alimentation humaine-Légumes-kt-TEND | N103: =MATCH(M103,'[1]Données Agriculture'!$M:$M,FALSE) -> 507
A104: Bilan d'approvisionnement | B104: Alimentation humaine | C104: Viande | D104: kt | E104: TEND | F104: 5386.8199 | G104: 5436.7953 | H104: 5488.25 | I104: 5530.2378 | J104: 5557.2376 | K104: 5565.8671 | L104: 5555.3994 | M104: =A104&"-"&B104&"-"&C104&"-"&D104&"-"&E104 -> Bilan d'approvisionnement-Alimentation humaine-Viande-kt-TEND | N104: =MATCH(M104,'[1]Données Agriculture'!$M:$M,FALSE) -> 512
... A153: Bioénergies | B153: Biomasse | C153: Total hors forêt et produits dérivés du bois | D153: TWh | E153: TEND | F153: 147.50219 | G153: 147.2965 | H153: 147.45537 | I153: 148.83172 | J153: 150.27377 | K153: 148.57602 | L153: 142.50039 | M153: =A153&"-"&B153&"-"&C153&"-"&D153&"-"&E153 -> Bioénergies-Biomasse-Total hors forêt et produits dérivés du bois-TWh-TEND | N153: =MATCH(M153,'[1]Données Agriculture'!$M:$M,FALSE) -> 752
A154: Changement d'usage des terres | C154: Autres surfaces_reste_Autres surfaces | D154: kha | E154: TEND | F154: 3371.7315 | G154: 3371.7315 | H154: 3371.7315 | I154: 3371.7315 | J154: 3371.7315 | K154: 3371.7315 | L154: 3371.7315 | M154: =A154&"-"&B154&"-"&C154&"-"&D154&"-"&E154 -> Changement d'usage des terres--Autres surfaces_reste_Autres surfaces-kha-TEND | N154: =MATCH(M154,'[1]Données Agriculture'!$M:$M,FALSE) -> 762
...

Sheet COMPARAISONS_2050
E1: VERSION 2025 | U1: VERSION 2021 | AB1: Comparaison RUN 3 bis AMS | AD1: Comparaison RUN 3 bis AMS | AH1: COMPARAISON v2025/v2021
U2: MISSIONS_BIORESSOURCES/2000_CHCO_Extractions_Trajectoires_ADEME/2023_06_26_Trajectoire2050_pas_5_ans.xlsx' | V2: MISSIONS_BIORESSOURCES/2000_CHCO_Extractions_Trajectoires_ADEME/2023_06_26_Trajectoire2050_pas_5_ans.xlsx' | AH2: MISSIONS_BIORESSOURCES/2000_CHCO_Extractions_Trajectoires_ADEME/2023_06_26_Trajectoire2050_pas_5_ans.xlsx' | AI2: MISSIONS_BIORESSOURCES/2000_CHCO_Extractions_Trajectoires_ADEME/2023_06_26_Trajectoire2050_pas_5_ans.xlsx'
U3: FORMULES A RECOPIER
S4: =C4&"-"&D4 -> - | T4: =MATCH($S4,[2]S0!$R:$R,FALSE) -> 185 | U4: {=IFERROR(INDIRECT(ADDRESS($T4,U$7,,,U$10)),"-")} -> - | V4: {=IFERROR(INDIRECT(ADDRESS($T4,V$7,,,V$10)),"-")} -> - | W4: {=IFERROR(INDIRECT(ADDRESS($T4,W$7,,,W$10)),"-")} -> - | X4: {=IFERROR(INDIRECT(ADDRESS($T4,X$7,,,X$10)),"-")} -> - | Y4: {=IFERROR(INDIRECT(ADDRESS($T4,Y$7,,,Y$10)),"-")} -> - | Z4: {=IFERROR(INDIRECT(ADDRESS($T4,Z$7,,,Z$10)),"-")} -> - | AB4: =IFERROR(MATCH(S4,[3]AMS_RUN3_2050!$I:$I,FALSE),"non") -> 316 | AC4: 66999.161 | AD4: =IFERROR(MATCH($S4,[4]AMS_RUN3_2030!$I:$I,FALSE),"non") -> 316 | AE4: {=IFERROR(INDIRECT(ADDRESS($AD4,8,,,AE$10)),"non")} -> non
U5: [2023_06_26_Trajectoire2050_pas_5_ans.xlsx] | AC5: [AMS_RUN3_bis_2050_V2.xlsx] | AE5: [AMS_RUN_3_2030_V4.xlsx] | AH5: [2023_06_26_Trajectoire2050_pas_5_ans.xlsx]
U7: =COLUMN([5]S0!$I$6) -> 9 | V7: =COLUMN([5]S1!$O$6) -> 15 | W7: =COLUMN([5]S1!$O$6) -> 15 | X7: =COLUMN([5]S1!$O$6) -> 15 | Y7: =COLUMN([5]S1!$O$6) -> 15 | Z7: =COLUMN([5]S1!$O$6) -> 15
E8: S0 - Contrefactuel_2025_v1 | F8: S0 - Contrefactuel_2025_v1 | G8: S1 - Génération frugale_2025_v1 | H8: S2 - Coopérations territoriales_2025_v1 | I8: S3 - Technologies vertes_2025_v1 | J8: S4 - Pari réparateur_2025_v1 | U8: 2020 | V8: 2050 | W8: 2050 | X8: 2050 | Y8: 2050 | Z8: 2050
A9: Catégorie | B9: Sous-catégorie | C9: Variable | D9: Unité | E9: 2020 | F9: TEND | G9: S1 | H9: S2 | I9: S3 | J9: S4 | L9: Cat&SsCat&Var | M9: Index | N9: Catégorie | O9: Sous-catégorie | P9: Variable | Q9: Unité | U9: S0 | V9: S0 | W9: S1 | X9: S2 | Y9: S3 | Z9: S4 | AC9: AMS_RUN3_2050 | AE9: AMS_RUN3_2030 | AH9: 2020 | AI9: S0 | AJ9: S1 | AK9: S2 | AL9: S3 | AM9: S4
E10: 2 | F10: 2 | G10: 601 | H10: 1200 | I10: 1799 | J10: 2398 | U10: =$U$5&U9 -> [2023_06_26_Trajectoire2050_pas_5_ans.xlsx]S0 | V10: =$U$5&V9 -> [2023_06_26_Trajectoire2050_pas_5_ans.xlsx]S0 | W10: =$U$5&W9 -> [2023_06_26_Trajectoire2050_pas_5_ans.xlsx]S1 | X10: =$U$5&X9 -> [2023_06_26_Trajectoire2050_pas_5_ans.xlsx]S2 | Y10: =$U$5&Y9 -> [2023_06_26_Trajectoire2050_pas_5_ans.xlsx]S3 | Z10: =$U$5&Z9 -> [2023_06_26_Trajectoire2050_pas_5_ans.xlsx]S4 | AC10: =$AC$5&AC9 -> [AMS_RUN3_bis_2050_V2.xlsx]AMS_RUN3_2050 | AE10: =$AE$5&AE9 -> [AMS_RUN_3_2030_V4.xlsx]AMS_RUN3_2030 | AH10: =$V$5&AH9 -> 2020 | AI10: =$V$5&AI9 -> S0 | AJ10: =$V$5&AJ9 -> S1 | AK10: =$V$5&AK9 -> S2 | AL10: =$V$5&AL9 -> S3 | AM10: =$V$5&AM9 -> S4
A11: - | B11: - | C11: Alimentation humaine
A12: - | B12: - | C12: Code scénario
A13: Alimentation Humaine | B13: Population | C13: Population | D13: Milliers de personnes | E13: =SUMIFS(ADEME!$F:$F,ADEME!$A:$A,$A13,ADEME!$B:$B,$B13,ADEME!$C:$C,$C13,ADEME!$D:$D,$D13,ADEME!$E:$E,F$9) -> 65123 | F13: =SUMIFS(ADEME!$L:$L,ADEME!$A:$A,$A13,ADEME!$B:$B,$B13,ADEME!$C:$C,$C13,ADEME!$D:$D,$D13,ADEME!$E:$E,F$9) -> 66733 | G13: =SUMIFS(ADEME!$L:$L,ADEME!$A:$A,$A13,ADEME!$B:$B,$B13,ADEME!$C:$C,$C13,ADEME!$D:$D,$D13,ADEME!$E:$E,G$9) -> 66733 | H13: =SUMIFS(ADEME!$L:$L,ADEME!$A:$A,$A13,ADEME!$B:$B,$B13,ADEME!$C:$C,$C13,ADEME!$D:$D,$D13,ADEME!$E:$E,H$9) -> 66733 | I13: =SUMIFS(ADEME!$L:$L,ADEME!$A:$A,$A13,ADEME!$B:$B,$B13,ADEME!$C:$C,$C13,ADEME!$D:$D,$D13,ADEME!$E:$E,I$9) -> 66733 | J13: =SUMIFS(ADEME!$L:$L,ADEME!$A:$A,$A13,ADEME!$B:$B,$B13,ADEME!$C:$C,$C13,ADEME!$D:$D,$D13,ADEME!$E:$E,J$9) -> 66733 | L13: =A13&"-"&B13&"-"&C13 -> Alimentation Humaine-Population-Population | M13: =MATCH(L13,[6]RESULTATS_4!$W:$W,FALSE) -> 50 | N13: {=IFERROR(INDEX([6]RESULTATS_4!G:G,$M13),"-")} -> Alimentation Humaine | O13: {=IFERROR(INDEX([6]RESULTATS_4!H:H,$M13),"-")} -> Population | P13: {=IFERROR(INDEX([6]RESULTATS_4!I:I,$M13),"-")} -> Population | Q13: {=IFERROR(INDEX([6]RESULTATS_4!J:J,$M13),"-")} -> Milliers de personnes | S13: =C13&"-"&D13 -> Population-Milliers de personnes | T13: =MATCH(S13,[2]S0!$R:$R,FALSE) -> 11 | U13: 65577 | V13: 69683 | W13: 69683 | X13: 69683 | Y13: 69683 | Z13: 69683 | AB13: 11 | AC13: 66999.161 | AD13: 11 | AE13: 66452.453 | AH13: =IF(AND(E13=0,U13=0),"ok 0",(E13/U13-1)*100) -> -0.6923159 | AI13: =IF(AND(F13=0,V13=0),"ok 0",(F13/V13-1)*100) -> -4.2334572 | AJ13: =IF(AND(G13=0,W13=0),"ok 0",(G13/W13-1)*100) -> -4.2334572 | AK13: =IF(AND(H13=0,X13=0),"ok 0",(H13/X13-1)*100) -> -4.2334572 | AL13: =IF(AND(I13=0,Y13=0),"ok 0",(I13/Y13-1)*100) -> -4.2334572 | AM13: =IF(AND(J13=0,Z13=0),"ok 0",(J13/Z13-1)*100) -> -4.2334572
A14: Alimentation Humaine | B14: Population | C14: Taille moyenne 20-59 ans, cm | D14: cm | E14: =SUMIFS(ADEME!$F:$F,ADEME!$A:$A,$A14,ADEME!$B:$B,$B14,ADEME!$C:$C,$C14,ADEME!$D:$D,$D14,ADEME!$E:$E,F$9) -> 171.40969 | F14: =SUMIFS(ADEME!$L:$L,ADEME!$A:$A,$A14,ADEME!$B:$B,$B14,ADEME!$C:$C,$C14,ADEME!$D:$D,$D14,ADEME!$E:$E,F$9) -> 175.34856 | G14: =SUMIFS(ADEME!$L:$L,ADEME!$A:$A,$A14,ADEME!$B:$B,$B14,ADEME!$C:$C,$C14,ADEME!$D:$D,$D14,ADEME!$E:$E,G$9) -> 175.34856 | H14: =SUMIFS(ADEME!$L:$L,ADEME!$A:$A,$A14,ADEME!$B:$B,$B14,ADEME!$C:$C,$C14,ADEME!$D:$D,$D14,ADEME!$E:$E,H$9) -> 175.34856 | I14: =SUMIFS(ADEME!$L:$L,ADEME!$A:$A,$A14,ADEME!$B:$B,$B14,ADEME!$C:$C,$C14,ADEME!$D:$D,$D14,ADEME!$E:$E,I$9) -> 175.34856 | J14: =SUMIFS(ADEME!$L:$L,ADEME!$A:$A,$A14,ADEME!$B:$B,$B14,ADEME!$C:$C,$C14,ADEME!$D:$D,$D14,ADEME!$E:$E,J$9) -> 175.34856 | L14: =A14&"-"&B14&"-"&C14 -> Alimentation Humaine-Population-Taille moyenne 20-59 ans, cm | M14: =MATCH(L14,[6]RESULTATS_4!$W:$W,FALSE) -> 51 | N14: {=IFERROR(INDEX([6]RESULTATS_4!G:G,$M14),"-")} -> Alimentation Humaine | O14: {=IFERROR(INDEX([6]RESULTATS_4!H:H,$M14),"-")} -> Population | P14: {=IFERROR(INDEX([6]RESULTATS_4!I:I,$M14),"-")} -> Taille moyenne 20-59 ans, cm | Q14: {=IFERROR(INDEX([6]RESULTATS_4!$J:$J,M14),"-")} -> cm | S14: =C14&"-"&D14 -> Taille moyenne 20-59 ans, cm-cm | U14: - | V14: - | W14: - | X14: - | Y14: - | Z14: - | AB14: non | AC14: non | AD14: non | AE14: non
A15: Alimentation Humaine | B15: Nutrition | C15: Indice de Masse Corporelle 20-59 ans | D15: sans unité | E15: =SUMIFS(ADEME!$F:$F,ADEME!$A:$A,$A15,ADEME!$B:$B,$B15,ADEME!$C:$C,$C15,ADEME!$D:$D,$D15,ADEME!$E:$E,F$9) -> 25.287686 | F15: =SUMIFS(ADEME!$L:$L,ADEME!$A:$A,$A15,ADEME!$B:$B,$B15,ADEME!$C:$C,$C15,ADEME!$D:$D,$D15,ADEME!$E:$E,F$9) -> 26.85863 | G15: =SUMIFS(ADEME!$L:$L,ADEME!$A:$A,$A15,ADEME!$B:$B,$B15,ADEME!$C:$C,$C15,ADEME!$D:$D,$D15,ADEME!$E:$E,G$9) -> 24.421924 | H15: =SUMIFS(ADEME!$L:$L,ADEME!$A:$A,$A15,ADEME!$B:$B,$B15,ADEME!$C:$C,$C15,ADEME!$D:$D,$D15,ADEME!$E:$E,H$9) -> 24.421924 | I15: =SUMIFS(ADEME!$L:$L,ADEME!$A:$A,$A15,ADEME!$B:$B,$B15,ADEME!$C:$C,$C15,ADEME!$D:$D,$D15,ADEME!$E:$E,I$9) -> 24.421924 | J15: =SUMIFS(ADEME!$L:$L,ADEME!$A:$A,$A15,ADEME!$B:$B,$B15,ADEME!$C:$C,$C15,ADEME!$D:$D,$D15,ADEME!$E:$E,J$9) -> 26.85863 | L15: =A15&"-"&B15&"-"&C15 -> Alimentation Humaine-Nutrition-Indice de Masse Corporelle 20-59 ans | M15: =MATCH(L15,[6]RESULTATS_4!$W:$W,FALSE) -> 44 | N15: {=IFERROR(INDEX([6]RESULTATS_4!G:G,$M15),"-")} -> Alimentation Humaine | O15: {=IFERROR(INDEX([6]RESULTATS_4!H:H,$M15),"-")} -> Nutrition | P15: {=IFERROR(INDEX([6]RESULTATS_4!I:I,$M15),"-")} -> Indice de Masse Corporelle 20-59 ans | Q15: {=IFERROR(INDEX([6]RESULTATS_4!$J:$J,M15),"-")} -> sans unité | S15: =C15&"-"&D15 -> Indice de Masse Corporelle 20-59 ans-sans unité | T15: =MATCH(S15,[2]S0!$R:$R,FALSE) -> #N/A | U15: 25.517746 | V15: 26.85863 | W15: 24.421924 | X15: 24.421924 | Y15: 24.421924 | Z15: 26.85863 | AB15: 15 | AC15: 24.421924 | AD15: 15 | AE15: 24.421924 | AH15: =IF(AND(E15=0,U15=0),"ok 0",(E15/U15-1)*100) -> -0.9015663 | AI15: =IF(AND(F15=0,V15=0),"ok 0",(F15/V15-1)*100) -> 0 | AJ15: =IF(AND(G15=0,W15=0),"ok 0",(G15/W15-1)*100) -> 0 | AK15: =IF(AND(H15=0,X15=0),"ok 0",(H15/X15-1)*100) -> 0 | AL15: =IF(AND(I15=0,Y15=0),"ok 0",(I15/Y15-1)*100) -> 0 | AM15: =IF(AND(J15=0,Z15=0),"ok 0",(J15/Z15-1)*100) -> 0
A16: Alimentation Humaine | B16: Population | C16: Masse moyenne 20-59 ans | D16: kg | E16: =SUMIFS(ADEME!$F:$F,ADEME!$A:$A,$A16,ADEME!$B:$B,$B16,ADEME!$C:$C,$C16,ADEME!$D:$D,$D16,ADEME!$E:$E,F$9) -> 74.298466 | F16: =SUMIFS(ADEME!$L:$L,ADEME!$A:$A,$A16,ADEME!$B:$B,$B16,ADEME!$C:$C,$C16,ADEME!$D:$D,$D16,ADEME!$E:$E,F$9) -> 82.58255 | G16: =SUMIFS(ADEME!$L:$L,ADEME!$A:$A,$A16,ADEME!$B:$B,$B16,ADEME!$C:$C,$C16,ADEME!$D:$D,$D16,ADEME!$E:$E,G$9) -> 75.09038 | H16: =SUMIFS(ADEME!$L:$L,ADEME!$A:$A,$A16,ADEME!$B:$B,$B16,ADEME!$C:$C,$C16,ADEME!$D:$D,$D16,ADEME!$E:$E,H$9) -> 75.09038 | I16: =SUMIFS(ADEME!$L:$L,ADEME!$A:$A,$A16,ADEME!$B:$B,$B16,ADEME!$C:$C,$C16,ADEME!$D:$D,$D16,ADEME!$E:$E,I$9) -> 75.09038 | J16: =SUMIFS(ADEME!$L:$L,ADEME!$A:$A,$A16,ADEME!$B:$B,$B16,ADEME!$C:$C,$C16,ADEME!$D:$D,$D16,ADEME!$E:$E,J$9) -> 82.58255 | L16: =A16&"-"&B16&"-"&C16 -> Alimentation Humaine-Population-Masse moyenne 20-59 ans | M16: =MATCH(L16,[6]RESULTATS_4!$W:$W,FALSE) -> 49 | N16: {=IFERROR(INDEX([6]RESULTATS_4!G:G,$M16),"-")} -> Alimentation Humaine | O16: {=IFERROR(INDEX([6]RESULTATS_4!H:H,$M16),"-")} -> Population | P16: {=IFERROR(INDEX([6]RESULTATS_4!I:I,$M16),"-")} -> Masse moyenne 20-59 ans | Q16: {=IFERROR(INDEX([6]RESULTATS_4!$J:$J,M16),"-")} -> kg | S16: =C16&"-"&D16 -> Masse moyenne 20-59 ans-kg | U16: - | V16: - | W16: - | X16: - | Y16: - | Z16: - | AB16: non | AC16: non | AD16: non | AE16: non
A17: Alimentation Humaine | B17: Nutrition | C17: Besoins en protéines (ANC) | D17: g/personne.jour | E17: =SUMIFS(ADEME!$F:$F,ADEME!$A:$A,$A17,ADEME!$B:$B,$B17,ADEME!$C:$C,$C17,ADEME!$D:$D,$D17,ADEME!$E:$E,F$9) -> 58.756503 | F17: =SUMIFS(ADEME!$L:$L,ADEME!$A:$A,$A17,ADEME!$B:$B,$B17,ADEME!$C:$C,$C17,ADEME!$D:$D,$D17,ADEME!$E:$E,F$9) -> 64.888123 | G17: =SUMIFS(ADEME!$L:$L,ADEME!$A:$A,$A17,ADEME!$B:$B,$B17,ADEME!$C:$C,$C17,ADEME!$D:$D,$D17,ADEME!$E:$E,G$9) -> 58.984442 | H17: =SUMIFS(ADEME!$L:$L,ADEME!$A:$A,$A17,ADEME!$B:$B,$B17,ADEME!$C:$C,$C17,ADEME!$D:$D,$D17,ADEME!$E:$E,H$9) -> 58.984442 | I17: =SUMIFS(ADEME!$L:$L,ADEME!$A:$A,$A17,ADEME!$B:$B,$B17,ADEME!$C:$C,$C17,ADEME!$D:$D,$D17,ADEME!$E:$E,I$9) -> 58.984442 | J17: =SUMIFS(ADEME!$L:$L,ADEME!$A:$A,$A17,ADEME!$B:$B,$B17,ADEME!$C:$C,$C17,ADEME!$D:$D,$D17,ADEME!$E:$E,J$9) -> 64.888123 | L17: =A17&"-"&B17&"-"&C17 -> Alimentation Humaine-Nutrition-Besoins en protéines (ANC) | M17: =MATCH(L17,[6]RESULTATS_4!$W:$W,FALSE) -> 40 | N17: {=IFERROR(INDEX([6]RESULTATS_4!G:G,$M17),"-")} -> Alimentation Humaine | O17: {=IFERROR(INDEX([6]RESULTATS_4!H:H,$M17),"-")} -> Nutrition | P17: {=IFERROR(INDEX([6]RESULTATS_4!I:I,$M17),"-")} -> Besoins en protéines (ANC) | Q17: {=IFERROR(INDEX([6]RESULTATS_4!$J:$J,M17),"-")} -> g/personne.jour | S17: =C17&"-"&D17 -> Besoins en protéines (ANC)-g/personne.jour | T17: =MATCH(S17,[2]S0!$R:$R,FALSE) -> 16 | U17: 59.251802 | V17: 65.108126 | W17: 59.186544 | X17: 59.186544 | Y17: 59.186544 | Z17: 65.108126 | AB17: 16 | AC17: 59.186544 | AD17: 16 | AE17: 59.186544 | AH17: =IF(AND(E17=0,U17=0),"ok 0",(E17/U17-1)*100) -> -0.83592208 | AI17: =IF(AND(F17=0,V17=0),"ok 0",(F17/V17-1)*100) -> -0.33790475 | AJ17: =IF(AND(G17=0,W17=0),"ok 0",(G17/W17-1)*100) -> -0.34146556 | AK17: =IF(AND(H17=0,X17=0),"ok 0",(H17/X17-1)*100) -> -0.34146556 | AL17: =IF(AND(I17=0,Y17=0),"ok 0",(I17/Y17-1)*100) -> -0.34146556 | AM17: =IF(AND(J17=0,Z17=0),"ok 0",(J17/Z17-1)*100) -> -0.33790475
A18: Alimentation Humaine | B18: Nutrition | C18: Surconsommation d'énergie | D18: % | E18: =SUMIFS(ADEME!$F:$F,ADEME!$A:$A,$A18,ADEME!$B:$B,$B18,ADEME!$C:$C,$C18,ADEME!$D:$D,$D18,ADEME!$E:$E,F$9) -> 0.25512211 | F18: =SUMIFS(ADEME!$L:$L,ADEME!$A:$A,$A18,ADEME!$B:$B,$B18,ADEME!$C:$C,$C18,ADEME!$D:$D,$D18,ADEME!$E:$E,F$9) -> 0.22127857 | G18: =SUMIFS(ADEME!$L:$L,ADEME!$A:$A,$A18,ADEME!$B:$B,$B18,ADEME!$C:$C,$C18,ADEME!$D:$D,$D18,ADEME!$E:$E,G$9) -> 0.092941979 | H18: =SUMIFS(ADEME!$L:$L,ADEME!$A:$A,$A18,ADEME!$B:$B,$B18,ADEME!$C:$C,$C18,ADEME!$D:$D,$D18,ADEME!$E:$E,H$9) -> 0.076074655 | I18: =SUMIFS(ADEME!$L:$L,ADEME!$A:$A,$A18,ADEME!$B:$B,$B18,ADEME!$C:$C,$C18,ADEME!$D:$D,$D18,ADEME!$E:$E,I$9) -> 0.056170411 | J18: =SUMIFS(ADEME!$L:$L,ADEME!$A:$A,$A18,ADEME!$B:$B,$B18,ADEME!$C:$C,$C18,ADEME!$D:$D,$D18,ADEME!$E:$E,J$9) -> 0.12561455 | L18: =A18&"-"&B18&"-"&C18 -> Alimentation Humaine-Nutrition-Surconsommation d'énergie | M18: =MATCH(L18,[6]RESULTATS_4!$W:$W,FALSE) -> 47 | N18: {=IFERROR(INDEX([6]RESULTATS_4!G:G,$M18),"-")} -> Alimentation Humaine | O18: {=IFERROR(INDEX([6]RESULTATS_4!H:H,$M18),"-")} -> Nutrition | P18: {=IFERROR(INDEX([6]RESULTATS_4!I:I,$M18),"-")} -> Surconsommation d'énergie | Q18: {=IFERROR(INDEX([6]RESULTATS_4!$J:$J,M18),"-")} -> % | S18: =C18&"-"&D18 -> Surconsommation d'énergie-% | T18: =MATCH(S18,[2]S0!$R:$R,FALSE) -> 20 | U18: 0.28451583 | V18: 0.24681406 | W18: 0.11466877 | X18: 0.1126875 | Y18: 0.10847081 | Z18: 0.1647367 | AB18: 20 | AC18: 0.45335322 | AD18: 20 | AE18: 0.43319627 | AH18: =IF(AND(E18=0,U18=0),"ok 0",(E18/U18-1)*100) -> -10.331135 | AI18: =IF(AND(F18=0,V18=0),"ok 0",(F18/V18-1)*100) -> -10.346044 | AJ18: =IF(AND(G18=0,W18=0),"ok 0",(G18/W18-1)*100) -> -18.947433 | AK18: =IF(AND(H18=0,X18=0),"ok 0",(H18/X18-1)*100) -> -32.490599 | AL18: =IF(AND(I18=0,Y18=0),"ok 0",(I18/Y18-1)*100) -> -48.216104 | AM18: =IF(AND(J18=0,Z18=0),"ok 0",(J18/Z18-1)*100) -> -23.748287 | AN18: révision calcul lait
A19: Alimentation Humaine | B19: Nutrition | C19: Surconsommation de protéines | D19: % | E19: =SUMIFS(ADEME!$F:$F,ADEME!$A:$A,$A19,ADEME!$B:$B,$B19,ADEME!$C:$C,$C19,ADEME!$D:$D,$D19,ADEME!$E:$E,F$9) -> 1.0240319 | F19: =SUMIFS(ADEME!$L:$L,ADEME!$A:$A,$A19,ADEME!$B:$B,$B19,ADEME!$C:$C,$C19,ADEME!$D:$D,$D19,ADEME!$E:$E,F$9) -> 0.88798942 | G19: =SUMIFS(ADEME!$L:$L,ADEME!$A:$A,$A19,ADEME!$B:$B,$B19,ADEME!$C:$C,$C19,ADEME!$D:$D,$D19,ADEME!$E:$E,G$9) -> 0.38801624 | H19: =SUMIFS(ADEME!$L:$L,ADEME!$A:$A,$A19,ADEME!$B:$B,$B19,ADEME!$C:$C,$C19,ADEME!$D:$D,$D19,ADEME!$E:$E,H$9) -> 0.51265725 | I19: =SUMIFS(ADEME!$L:$L,ADEME!$A:$A,$A19,ADEME!$B:$B,$B19,ADEME!$C:$C,$C19,ADEME!$D:$D,$D19,ADEME!$E:$E,I$9) -> 0.59481166 | J19: =SUMIFS(ADEME!$L:$L,ADEME!$A:$A,$A19,ADEME!$B:$B,$B19,ADEME!$C:$C,$C19,ADEME!$D:$D,$D19,ADEME!$E:$E,J$9) -> 0.86604119 | L19: =A19&"-"&B19&"-"&C19 -> Alimentation Humaine-Nutrition-Surconsommation de protéines | M19: =MATCH(L19,[6]RESULTATS_4!$W:$W,FALSE) -> 48 | N19: {=IFERROR(INDEX([6]RESULTATS_4!G:G,$M19),"-")} -> Alimentation Humaine | O19: {=IFERROR(INDEX([6]RESULTATS_4!H:H,$M19),"-")} -> Nutrition | P19: {=IFERROR(INDEX([6]RESULTATS_4!I:I,$M19),"-")} -> Surconsommation de protéines | Q19: {=IFERROR(INDEX([6]RESULTATS_4!$J:$J,M19),"-")} -> % | S19: =C19&"-"&D19 -> Surconsommation de protéines-% | T19: =MATCH(S19,[2]S0!$R:$R,FALSE) -> 18 | U19: 1.0576373 | V19: 0.88266326 | W19: 0.41853637 | X19: 0.55055347 | Y19: 0.63903531 | Z19: 0.90647447 | AB19: 18 | AC19: 1.2974271 | AD19: 18 | AE19: 1.2631966 | AH19: =IF(AND(E19=0,U19=0),"ok 0",(E19/U19-1)*100) -> -3.1774096 | AI19: =IF(AND(F19=0,V19=0),"ok 0",(F19/V19-1)*100) -> 0.60341841 | AJ19: =IF(AND(G19=0,W19=0),"ok 0",(G19/W19-1)*100) -> -7.2921087 | AK19: =IF(AND(H19=0,X19=0),"ok 0",(H19/X19-1)*100) -> -6.8832956 | AL19: =IF(AND(I19=0,Y19=0),"ok 0",(I19/Y19-1)*100) -> -6.9203758 | AM19: =IF(AND(J19=0,Z19=0),"ok 0",(J19/Z19-1)*100) -> -4.4604985
A20: Alimentation Humaine | B20: Gaspillage | C20: Pertes et gaspillages | D20: % | E20: =SUMIFS(ADEME!$F:$F,ADEME!$A:$A,$A20,ADEME!$B:$B,$B20,ADEME!$C:$C,$C20,ADEME!$D:$D,$D20,ADEME!$E:$E,F$9) -> 0.10803948 | F20: =SUMIFS(ADEME!$L:$L,ADEME!$A:$A,$A20,ADEME!$B:$B,$B20,ADEME!$C:$C,$C20,ADEME!$D:$D,$D20,ADEME!$E:$E,F$9) -> 0.091889483 | G20: =SUMIFS(ADEME!$L:$L,ADEME!$A:$A,$A20,ADEME!$B:$B,$B20,ADEME!$C:$C,$C20,ADEME!$D:$D,$D20,ADEME!$E:$E,G$9) -> 0.057980283 | H20: =SUMIFS(ADEME!$L:$L,ADEME!$A:$A,$A20,ADEME!$B:$B,$B20,ADEME!$C:$C,$C20,ADEME!$D:$D,$D20,ADEME!$E:$E,H$9) -> 0.057551361 | I20: =SUMIFS(ADEME!$L:$L,ADEME!$A:$A,$A20,ADEME!$B:$B,$B20,ADEME!$C:$C,$C20,ADEME!$D:$D,$D20,ADEME!$E:$E,I$9) -> 0.05632113 | J20: =SUMIFS(ADEME!$L:$L,ADEME!$A:$A,$A20,ADEME!$B:$B,$B20,ADEME!$C:$C,$C20,ADEME!$D:$D,$D20,ADEME!$E:$E,J$9) -> 0.056957088 | L20: =A20&"-"&B20&"-"&C20 -> Alimentation Humaine-Gaspillage-Pertes et gaspillages | M20: =MATCH(L20,[6]RESULTATS_4!$W:$W,FALSE) -> 38 | N20: {=IFERROR(INDEX([6]RESULTATS_4!G:G,$M20),"-")} -> Alimentation Humaine | O20: {=IFERROR(INDEX([6]RESULTATS_4!H:H,$M20),"-")} -> Gaspillage | P20: {=IFERROR(INDEX([6]RESULTATS_4!I:I,$M20),"-")} -> Pertes et gaspillages | Q20: {=IFERROR(INDEX([6]RESULTATS_4!$J:$J,M20),"-")} -> % | S20: =C20&"-"&D20 -> Pertes et gaspillages-% | T20: =MATCH(S20,[2]S0!$R:$R,FALSE) -> 22 | U20: 0.11053087 | V20: 0.092194431 | W20: 0.058416753 | X20: 0.057695743 | Y20: 0.056635121 | Z20: 0.057561516 | AB20: 22 | AC20: 0.048224566 | AD20: 22 | AE20: 0.091390388 | AH20: =IF(AND(E20=0,U20=0),"ok 0",(E20/U20-1)*100) -> -2.2540268 | AI20: =IF(AND(F20=0,V20=0),"ok 0",(F20/V20-1)*100) -> -0.33076669 | AJ20: =IF(AND(G20=0,W20=0),"ok 0",(G20/W20-1)*100) -> -0.74716565 | AK20: =IF(AND(H20=0,X20=0),"ok 0",(H20/X20-1)*100) -> -0.25024657 | AL20: =IF(AND(I20=0,Y20=0),"ok 0",(I20/Y20-1)*100) -> -0.55440953 | AM20: =IF(AND(J20=0,Z20=0),"ok 0",(J20/Z20-1)*100) -> -1.0500557
A21: Alimentation Humaine | B21: Nutrition | C21: Proportion de protéines végétales | D21: % | E21: =SUMIFS(ADEME!$F:$F,ADEME!$A:$A,$A21,ADEME!$B:$B,$B21,ADEME!$C:$C,$C21,ADEME!$D:$D,$D21,ADEME!$E:$E,F$9) -> 0.37340483 | F21: =SUMIFS(ADEME!$L:$L,ADEME!$A:$A,$A21,ADEME!$B:$B,$B21,ADEME!$C:$C,$C21,ADEME!$D:$D,$D21,ADEME!$E:$E,F$9) -> 0.37902803 | G21: =SUMIFS(ADEME!$L:$L,ADEME!$A:$A,$A21,ADEME!$B:$B,$B21,ADEME!$C:$C,$C21,ADEME!$D:$D,$D21,ADEME!$E:$E,G$9) -> 0.51335641 | H21: =SUMIFS(ADEME!$L:$L,ADEME!$A:$A,$A21,ADEME!$B:$B,$B21,ADEME!$C:$C,$C21,ADEME!$D:$D,$D21,ADEME!$E:$E,H$9) -> 0.43839688 | I21: =SUMIFS(ADEME!$L:$L,ADEME!$A:$A,$A21,ADEME!$B:$B,$B21,ADEME!$C:$C,$C21,ADEME!$D:$D,$D21,ADEME!$E:$E,I$9) -> 0.38780418 | J21: =SUMIFS(ADEME!$L:$L,ADEME!$A:$A,$A21,ADEME!$B:$B,$B21,ADEME!$C:$C,$C21,ADEME!$D:$D,$D21,ADEME!$E:$E,J$9) -> 0.33197594 | L21: =A21&"-"&B21&"-"&C21 -> Alimentation Humaine-Nutrition-Proportion de protéines végétales | M21: =MATCH(L21,[6]RESULTATS_4!$W:$W,FALSE) -> 45 | N21: {=IFERROR(INDEX([6]RESULTATS_4!G:G,$M21),"-")} -> Alimentation Humaine | O21: {=IFERROR(INDEX([6]RESULTATS_4!H:H,$M21),"-")} -> Nutrition | P21: {=IFERROR(INDEX([6]RESULTATS_4!I:I,$M21),"-")} -> Proportion de protéines végétales | Q21: {=IFERROR(INDEX([6]RESULTATS_4!$J:$J,M21),"-")} -> % | S21: =C21&"-"&D21 -> Proportion de protéines végétales-% | T21: =MATCH(S21,[2]S0!$R:$R,FALSE) -> 19 | U21: 0.35746421 | V21: 0.36786756 | W21: 0.50640987 | X21: 0.43298238 | Y21: 0.3833252 | Z21: 0.33642692 | AB21: 19 | AC21: 0.40197771 | AD21: 19 | AE21: 0.37493322 | AH21: =IF(AND(E21=0,U21=0),"ok 0",(E21/U21-1)*100) -> 4.4593601 | AI21: =IF(AND(F21=0,V21=0),"ok 0",(F21/V21-1)*100) -> 3.0338272 | AJ21: =IF(AND(G21=0,W21=0),"ok 0",(G21/W21-1)*100) -> 1.3717245 | AK21: =IF(AND(H21=0,X21=0),"ok 0",(H21/X21-1)*100) -> 1.2505117 | AL21: =IF(AND(I21=0,Y21=0),"ok 0",(I21/Y21-1)*100) -> 1.1684555 | AM21: =IF(AND(J21=0,Z21=0),"ok 0",(J21/Z21-1)*100) -> -1.3230151
A22: Alimentation Humaine | B22: Nutrition | C22: Apports en calcium du lait | D22: mg/jour | E22: =SUMIFS(ADEME!$F:$F,ADEME!$A:$A,$A22,ADEME!$B:$B,$B22,ADEME!$C:$C,$C22,ADEME!$D:$D,$D22,ADEME!$E:$E,F$9) -> 899.14386 | F22: =SUMIFS(ADEME!$L:$L,ADEME!$A:$A,$A22,ADEME!$B:$B,$B22,ADEME!$C:$C,$C22,ADEME!$D:$D,$D22,ADEME!$E:$E,F$9) -> 856.25572 | G22: =SUMIFS(ADEME!$L:$L,ADEME!$A:$A,$A22,ADEME!$B:$B,$B22,ADEME!$C:$C,$C22,ADEME!$D:$D,$D22,ADEME!$E:$E,G$9) -> 635.15602 | H22: =SUMIFS(ADEME!$L:$L,ADEME!$A:$A,$A22,ADEME!$B:$B,$B22,ADEME!$C:$C,$C22,ADEME!$D:$D,$D22,ADEME!$E:$E,H$9) -> 685.67183 | I22: =SUMIFS(ADEME!$L:$L,ADEME!$A:$A,$A22,ADEME!$B:$B,$B22,ADEME!$C:$C,$C22,ADEME!$D:$D,$D22,ADEME!$E:$E,I$9) -> 692.89195 | J22: =SUMIFS(ADEME!$L:$L,ADEME!$A:$A,$A22,ADEME!$B:$B,$B22,ADEME!$C:$C,$C22,ADEME!$D:$D,$D22,ADEME!$E:$E,J$9) -> 811.63516 | L22: =A22&"-"&B22&"-"&C22 -> Alimentation Humaine-Nutrition-Apports en calcium du lait | M22: =MATCH(L22,[6]RESULTATS_4!$W:$W,FALSE) -> 39 | N22: {=IFERROR(INDEX([6]RESULTATS_4!G:G,$M22),"-")} -> Alimentation Humaine | O22: {=IFERROR(INDEX([6]RESULTATS_4!H:H,$M22),"-")} -> Nutrition | P22: {=IFERROR(INDEX([6]RESULTATS_4!I:I,$M22),"-")} -> Apports en calcium du lait | Q22: {=IFERROR(INDEX([6]RESULTATS_4!$J:$J,M22),"-")} -> mg/jour | S22: =C22&"-"&D22 -> Apports en calcium du lait-mg/jour | T22: =MATCH(S22,[2]S0!$R:$R,FALSE) -> 21 | U22: 990.10614 | V22: 990.47913 | W22: 723.8382 | X22: 786.52783 | Y22: 797.5208 | Z22: 930.23112 | AB22: 21 | AC22: 1064.7866 | AD22: 21 | AE22: 1027.979 | AH22: =IF(AND(E22=0,U22=0),"ok 0",(E22/U22-1)*100) -> -9.187124 | AI22: =IF(AND(F22=0,V22=0),"ok 0",(F22/V22-1)*100) -> -13.551361 | AJ22: =IF(AND(G22=0,W22=0),"ok 0",(G22/W22-1)*100) -> -12.251657 | AK22: =IF(AND(H22=0,X22=0),"ok 0",(H22/X22-1)*100) -> -12.822941 | AL22: =IF(AND(I22=0,Y22=0),"ok 0",(I22/Y22-1)*100) -> -13.119263 | AM22: =IF(AND(J22=0,Z22=0),"ok 0",(J22/Z22-1)*100) -> -12.749086 | AN22: révision calcul lait
A23: Alimentation Humaine | B23: Nutrition | C23: Disponibilité en protéines | D23: g/personne.jour | E23: =SUMIFS(ADEME!$F:$F,ADEME!$A:$A,$A23,ADEME!$B:$B,$B23,ADEME!$C:$C,$C23,ADEME!$D:$D,$D23,ADEME!$E:$E,F$9) -> 118.92503 | F23: =SUMIFS(ADEME!$L:$L,ADEME!$A:$A,$A23,ADEME!$B:$B,$B23,ADEME!$C:$C,$C23,ADEME!$D:$D,$D23,ADEME!$E:$E,F$9) -> 122.50809 | G23: =SUMIFS(ADEME!$L:$L,ADEME!$A:$A,$A23,ADEME!$B:$B,$B23,ADEME!$C:$C,$C23,ADEME!$D:$D,$D23,ADEME!$E:$E,G$9) -> 81.871364 | H23: =SUMIFS(ADEME!$L:$L,ADEME!$A:$A,$A23,ADEME!$B:$B,$B23,ADEME!$C:$C,$C23,ADEME!$D:$D,$D23,ADEME!$E:$E,H$9) -> 89.223244 | I23: =SUMIFS(ADEME!$L:$L,ADEME!$A:$A,$A23,ADEME!$B:$B,$B23,ADEME!$C:$C,$C23,ADEME!$D:$D,$D23,ADEME!$E:$E,I$9) -> 94.069076 | J23: =SUMIFS(ADEME!$L:$L,ADEME!$A:$A,$A23,ADEME!$B:$B,$B23,ADEME!$C:$C,$C23,ADEME!$D:$D,$D23,ADEME!$E:$E,J$9) -> 121.08391 | L23: =A23&"-"&B23&"-"&C23 -> Alimentation Humaine-Nutrition-Disponibilité en protéines | M23: =MATCH(L23,[6]RESULTATS_4!$W:$W,FALSE) -> 43 | N23: {=IFERROR(INDEX([6]RESULTATS_4!G:G,$M23),"-")} -> Alimentation Humaine | O23: {=IFERROR(INDEX([6]RESULTATS_4!H:H,$M23),"-")} -> Nutrition | P23: {=IFERROR(INDEX([6]RESULTATS_4!I:I,$M23),"-")} -> Disponibilité en protéines | Q23: {=IFERROR(INDEX([6]RESULTATS_4!$J:$J,M23),"-")} -> g/personne.jour | S23: =C23&"-"&D23 -> Disponibilité en protéines-g/personne.jour | T23: =MATCH(S23,[2]S0!$R:$R,FALSE) -> 17 | U23: 121.91872 | V23: 122.57668 | W23: 83.958265 | X23: 91.771901 | Y23: 97.008835 | Z23: 124.12698 | AB23: non | AC23: non | AD23: non | AE23: non | AH23: =IF(AND(E23=0,U23=0),"ok 0",(E23/U23-1)*100) -> -2.4554764 | AI23: =IF(AND(F23=0,V23=0),"ok 0",(F23/V23-1)*100) -> -0.055955487 | AJ23: =IF(AND(G23=0,W23=0),"ok 0",(G23/W23-1)*100) -> -2.4856412 | AK23: =IF(AND(H23=0,X23=0),"ok 0",(H23/X23-1)*100) -> -2.7771649 | AL23: =IF(AND(I23=0,Y23=0),"ok 0",(I23/Y23-1)*100) -> -3.0304031 | AM23: =IF(AND(J23=0,Z23=0),"ok 0",(J23/Z23-1)*100) -> -2.4515787
A24: Alimentation Humaine | B24: Nutrition | C24: Protéines animales, g/jour | D24: g/personne.jour | E24: =SUMIFS(ADEME!$F:$F,ADEME!$A:$A,$A24,ADEME!$B:$B,$B24,ADEME!$C:$C,$C24,ADEME!$D:$D,$D24,ADEME!$E:$E,F$9) -> 74.517852 | F24: =SUMIFS(ADEME!$L:$L,ADEME!$A:$A,$A24,ADEME!$B:$B,$B24,ADEME!$C:$C,$C24,ADEME!$D:$D,$D24,ADEME!$E:$E,F$9) -> 76.07409 | G24: =SUMIFS(ADEME!$L:$L,ADEME!$A:$A,$A24,ADEME!$B:$B,$B24,ADEME!$C:$C,$C24,ADEME!$D:$D,$D24,ADEME!$E:$E,G$9) -> 39.842174 | H24: =SUMIFS(ADEME!$L:$L,ADEME!$A:$A,$A24,ADEME!$B:$B,$B24,ADEME!$C:$C,$C24,ADEME!$D:$D,$D24,ADEME!$E:$E,H$9) -> 50.108052 | I24: =SUMIFS(ADEME!$L:$L,ADEME!$A:$A,$A24,ADEME!$B:$B,$B24,ADEME!$C:$C,$C24,ADEME!$D:$D,$D24,ADEME!$E:$E,I$9) -> 57.588695 | J24: =SUMIFS(ADEME!$L:$L,ADEME!$A:$A,$A24,ADEME!$B:$B,$B24,ADEME!$C:$C,$C24,ADEME!$D:$D,$D24,ADEME!$E:$E,J$9) -> 80.886965 | L24: =A24&"-"&B24&"-"&C24 -> Alimentation Humaine-Nutrition-Protéines animales, g/jour | M24: =MATCH(L24,[6]RESULTATS_4!$W:$W,FALSE) -> 46 | N24: {=IFERROR(INDEX([6]RESULTATS_4!G:G,$M24),"-")} -> Alimentation Humaine | O24: {=IFERROR(INDEX([6]RESULTATS_4!H:H,$M24),"-")} -> Nutrition | P24: {=IFERROR(INDEX([6]RESULTATS_4!I:I,$M24),"-")} -> Protéines animales, g/jour | Q24: {=IFERROR(INDEX([6]RESULTATS_4!$J:$J,M24),"-")} -> g/personne.jour | S24: =C24&"-"&D24 -> Protéines animales, g/jour-g/personne.jour | U24: - | V24: - | W24: - | X24: - | Y24: - | Z24: - | AB24: non | AC24: non | AD24: non | AE24: non
A25: Alimentation Humaine | B25: Nutrition | C25: Besoins en protéines (kt) | D25: kt | E25: =SUMIFS(ADEME!$F:$F,ADEME!$A:$A,$A25,ADEME!$B:$B,$B25,ADEME!$C:$C,$C25,ADEME!$D:$D,$D25,ADEME!$E:$E,F$9) -> 1168.8273 | F25: =SUMIFS(ADEME!$L:$L,ADEME!$A:$A,$A25,ADEME!$B:$B,$B25,ADEME!$C:$C,$C25,ADEME!$D:$D,$D25,ADEME!$E:$E,F$9) -> 1335.4633 | G25: =SUMIFS(ADEME!$L:$L,ADEME!$A:$A,$A25,ADEME!$B:$B,$B25,ADEME!$C:$C,$C25,ADEME!$D:$D,$D25,ADEME!$E:$E,G$9) -> 1221.6121 | H25: =SUMIFS(ADEME!$L:$L,ADEME!$A:$A,$A25,ADEME!$B:$B,$B25,ADEME!$C:$C,$C25,ADEME!$D:$D,$D25,ADEME!$E:$E,H$9) -> 1221.6121 | I25: =SUMIFS(ADEME!$L:$L,ADEME!$A:$A,$A25,ADEME!$B:$B,$B25,ADEME!$C:$C,$C25,ADEME!$D:$D,$D25,ADEME!$E:$E,I$9) -> 1221.6121 | J25: =SUMIFS(ADEME!$L:$L,ADEME!$A:$A,$A25,ADEME!$B:$B,$B25,ADEME!$C:$C,$C25,ADEME!$D:$D,$D25,ADEME!$E:$E,J$9) -> 1335.4633 | L25: =A25&"-"&B25&"-"&C25 -> Alimentation Humaine-Nutrition-Besoins en protéines (kt) | M25: =MATCH(L25,[6]RESULTATS_4!$W:$W,FALSE) -> 41 | N25: {=IFERROR(INDEX([6]RESULTATS_4!G:G,$M25),"-")} -> Alimentation Humaine | O25: {=IFERROR(INDEX([6]RESULTATS_4!H:H,$M25),"-")} -> Nutrition | P25: {=IFERROR(INDEX([6]RESULTATS_4!I:I,$M25),"-")} -> Besoins en protéines (kt) | Q25: {=IFERROR(INDEX([6]RESULTATS_4!$J:$J,M25),"-")} -> kt | S25: =C25&"-"&D25 -> Besoins en protéines (kt)-kt | T25: =MATCH(S25,[2]S0!$R:$R,FALSE) -> #N/A | U25: 1189.1486 | V25: 1392.23 | W25: 1272.1149 | X25: 1272.1149 | Y25: 1272.1149 | Z25: 1392.23 | AB25: non | AC25: non | AD25: non | AE25: non | AH25: =IF(AND(E25=0,U25=0),"ok 0",(E25/U25-1)*100) -> -1.7088928 | AI25: =IF(AND(F25=0,V25=0),"ok 0",(F25/V25-1)*100) -> -4.0773885 | AJ25: =IF(AND(G25=0,W25=0),"ok 0",(G25/W25-1)*100) -> -3.9699887 | AK25: =IF(AND(H25=0,X25=0),"ok 0",(H25/X25-1)*100) -> -3.9699887 | AL25: =IF(AND(I25=0,Y25=0),"ok 0",(I25/Y25-1)*100) -> -3.9699887 | AM25: =IF(AND(J25=0,Z25=0),"ok 0",(J25/Z25-1)*100) -> -4.0773885 | AN25: revision population
A26: Alimentation Humaine | B26: Nutrition | C26: Disponibilité alimentaire en protéines (kt) | D26: kt | E26: =SUMIFS(ADEME!$F:$F,ADEME!$A:$A,$A26,ADEME!$B:$B,$B26,ADEME!$C:$C,$C26,ADEME!$D:$D,$D26,ADEME!$E:$E,F$9) -> 2365.7437 | F26: =SUMIFS(ADEME!$L:$L,ADEME!$A:$A,$A26,ADEME!$B:$B,$B26,ADEME!$C:$C,$C26,ADEME!$D:$D,$D26,ADEME!$E:$E,F$9) -> 2521.3406 | G26: =SUMIFS(ADEME!$L:$L,ADEME!$A:$A,$A26,ADEME!$B:$B,$B26,ADEME!$C:$C,$C26,ADEME!$D:$D,$D26,ADEME!$E:$E,G$9) -> 1695.6174 | H26: =SUMIFS(ADEME!$L:$L,ADEME!$A:$A,$A26,ADEME!$B:$B,$B26,ADEME!$C:$C,$C26,ADEME!$D:$D,$D26,ADEME!$E:$E,H$9) -> 1847.8804 | I26: =SUMIFS(ADEME!$L:$L,ADEME!$A:$A,$A26,ADEME!$B:$B,$B26,ADEME!$C:$C,$C26,ADEME!$D:$D,$D26,ADEME!$E:$E,I$9) -> 1948.2412 | J26: =SUMIFS(ADEME!$L:$L,ADEME!$A:$A,$A26,ADEME!$B:$B,$B26,ADEME!$C:$C,$C26,ADEME!$D:$D,$D26,ADEME!$E:$E,J$9) -> 2492.0296 | L26: =A26&"-"&B26&"-"&C26 -> Alimentation Humaine-Nutrition-Disponibilité alimentaire en protéines (kt) | M26: =MATCH(L26,[6]RESULTATS_4!$W:$W,FALSE) -> 42 | N26: {=IFERROR(INDEX([6]RESULTATS_4!G:G,$M26),"-")} -> Alimentation Humaine | O26: {=IFERROR(INDEX([6]RESULTATS_4!H:H,$M26),"-")} -> Nutrition | P26: {=IFERROR(INDEX([6]RESULTATS_4!I:I,$M26),"-")} -> Disponibilité alimentaire en protéines (kt) | Q26: {=IFERROR(INDEX([6]RESULTATS_4!$J:$J,M26),"-")} -> kt | S26: =C26&"-"&D26 -> Disponibilité alimentaire en protéines (kt)-kt | T26: =MATCH(S26,[2]S0!$R:$R,FALSE) -> #N/A | U26: 1849.8124 | V26: 1984.7493 | W26: 1337.1072 | X26: 1464.5649 | Y26: 1570.025 | Z26: 2056.6074 | AB26: non | AC26: non | AD26: non | AE26: non | AH26: =IF(AND(E26=0,U26=0),"ok 0",(E26/U26-1)*100) -> 27.891004 | AI26: =IF(AND(F26=0,V26=0),"ok 0",(F26/V26-1)*100) -> 27.035721 | AJ26: =IF(AND(G26=0,W26=0),"ok 0",(G26/W26-1)*100) -> 26.81238 | AK26: =IF(AND(H26=0,X26=0),"ok 0",(H26/X26-1)*100) -> 26.172652 | AL26: =IF(AND(I26=0,Y26=0),"ok 0",(I26/Y26-1)*100) -> 24.089819 | AM26: =IF(AND(J26=0,Z26=0),"ok 0",(J26/Z26-1)*100) -> 21.171866 | AN26: Modification de l'indicateur
A27: Alimentation Humaine | B27: Assiette | C27: Céréales | D27: g éq. primaire/jour | E27: =SUMIFS(ADEME!$F:$F,ADEME!$A:$A,$A27,ADEME!$B:$B,$B27,ADEME!$C:$C,$C27,ADEME!$D:$D,$D27,ADEME!$E:$E,F$9) -> 309.29655 | F27: =SUMIFS(ADEME!$L:$L,ADEME!$A:$A,$A27,ADEME!$B:$B,$B27,ADEME!$C:$C,$C27,ADEME!$D:$D,$D27,ADEME!$E:$E,F$9) -> 307.27292 | G27: =SUMIFS(ADEME!$L:$L,ADEME!$A:$A,$A27,ADEME!$B:$B,$B27,ADEME!$C:$C,$C27,ADEME!$D:$D,$D27,ADEME!$E:$E,G$9) -> 268.42465 | H27: =SUMIFS(ADEME!$L:$L,ADEME!$A:$A,$A27,ADEME!$B:$B,$B27,ADEME!$C:$C,$C27,ADEME!$D:$D,$D27,ADEME!$E:$E,H$9) -> 253.16498 | I27: =SUMIFS(ADEME!$L:$L,ADEME!$A:$A,$A27,ADEME!$B:$B,$B27,ADEME!$C:$C,$C27,ADEME!$D:$D,$D27,ADEME!$E:$E,I$9) -> 238.41124 | J27: =SUMIFS(ADEME!$L:$L,ADEME!$A:$A,$A27,ADEME!$B:$B,$B27,ADEME!$C:$C,$C27,ADEME!$D:$D,$D27,ADEME!$E:$E,J$9) -> 275.2401 | L27: =A27&"-"&B27&"-"&C27 -> Alimentation Humaine-Assiette-Céréales | M27: =MATCH(L27,[6]RESULTATS_4!$W:$W,FALSE) -> 25 | N27: {=IFERROR(INDEX([6]RESULTATS_4!G:G,$M27),"-")} -> Alimentation Humaine | O27: {=IFERROR(INDEX([6]RESULTATS_4!H:H,$M27),"-")} -> Assiette | P27: {=IFERROR(INDEX([6]RESULTATS_4!I:I,$M27),"-")} -> Céréales | Q27: {=IFERROR(INDEX([6]RESULTATS_4!$J:$J,M27),"-")} -> g éq. primaire/jour | S27: =C27&"-"&D27 -> Céréales-g éq. primaire/jour | T27: =MATCH(S27,[2]S0!$R:$R,FALSE) -> 23 | U27: 382.33161 | V27: 339.1275 | W27: 315.89867 | X27: 299.64665 | Y27: 284.44135 | Z27: 330.10731 | AB27: 23 | AC27: 397.4634 | AD27: 23 | AE27: 390.83901 | AH27: =IF(AND(E27=0,U27=0),"ok 0",(E27/U27-1)*100) -> -19.102542 | AI27: =IF(AND(F27=0,V27=0),"ok 0",(F27/V27-1)*100) -> -9.3930994 | AJ27: =IF(AND(G27=0,W27=0),"ok 0",(G27/W27-1)*100) -> -15.028243 | AK27: =IF(AND(H27=0,X27=0),"ok 0",(H27/X27-1)*100) -> -15.51216 | AL27: =IF(AND(I27=0,Y27=0),"ok 0",(I27/Y27-1)*100) -> -16.182636 | AM27: =IF(AND(J27=0,Z27=0),"ok 0",(J27/Z27-1)*100) -> -16.621025 | AN27: revision population+corrections mineures assiette
A28: Alimentation Humaine | B28: Assiette | C28: Pommes de terre | D28: g éq. primaire/jour | E28: =SUMIFS(ADEME!$F:$F,ADEME!$A:$A,$A28,ADEME!$B:$B,$B28,ADEME!$C:$C,$C28,ADEME!$D:$D,$D28,ADEME!$E:$E,F$9) -> 158.48198 | F28: =SUMIFS(ADEME!$L:$L,ADEME!$A:$A,$A28,ADEME!$B:$B,$B28,ADEME!$C:$C,$C28,ADEME!$D:$D,$D28,ADEME!$E:$E,F$9) -> 182.48443 | G28: =SUMIFS(ADEME!$L:$L,ADEME!$A:$A,$A28,ADEME!$B:$B,$B28,ADEME!$C:$C,$C28,ADEME!$D:$D,$D28,ADEME!$E:$E,G$9) -> 115.06869 | H28: =SUMIFS(ADEME!$L:$L,ADEME!$A:$A,$A28,ADEME!$B:$B,$B28,ADEME!$C:$C,$C28,ADEME!$D:$D,$D28,ADEME!$E:$E,H$9) -> 123.91393 | I28: =SUMIFS(ADEME!$L:$L,ADEME!$A:$A,$A28,ADEME!$B:$B,$B28,ADEME!$C:$C,$C28,ADEME!$D:$D,$D28,ADEME!$E:$E,I$9) -> 128.33655 | J28: =SUMIFS(ADEME!$L:$L,ADEME!$A:$A,$A28,ADEME!$B:$B,$B28,ADEME!$C:$C,$C28,ADEME!$D:$D,$D28,ADEME!$E:$E,J$9) -> 158.16498 | L28: =A28&"-"&B28&"-"&C28 -> Alimentation Humaine-Assiette-Pommes de terre | M28: =MATCH(L28,[6]RESULTATS_4!$W:$W,FALSE) -> 35 | N28: {=IFERROR(INDEX([6]RESULTATS_4!G:G,$M28),"-")} -> Alimentation Humaine | O28: {=IFERROR(INDEX([6]RESULTATS_4!H:H,$M28),"-")} -> Assiette | P28: {=IFERROR(INDEX([6]RESULTATS_4!I:I,$M28),"-")} -> Pommes de terre | Q28: {=IFERROR(INDEX([6]RESULTATS_4!$J:$J,M28),"-")} -> g éq. primaire/jour | S28: =C28&"-"&D28 -> Pommes de terre-g éq. primaire/jour | T28: =MATCH(S28,[2]S0!$R:$R,FALSE) -> 24 | U28: 145.2655 | V28: 165.44399 | W28: 105.84334 | X28: 113.96935 | Y28: 118.03236 | Z28: 143.41446 | AB28: 24 | AC28: 156.48244 | AD28: 24 | AE28: 150.23135 | AH28: =IF(AND(E28=0,U28=0),"ok 0",(E28/U28-1)*100) -> 9.0981577 | AI28: =IF(AND(F28=0,V28=0),"ok 0",(F28/V28-1)*100) -> 10.299822 | AJ28: =IF(AND(G28=0,W28=0),"ok 0",(G28/W28-1)*100) -> 8.7160359 | AK28: =IF(AND(H28=0,X28=0),"ok 0",(H28/X28-1)*100) -> 8.7256563 | AL28: =IF(AND(I28=0,Y28=0),"ok 0",(I28/Y28-1)*100) -> 8.7299697 | AM28: =IF(AND(J28=0,Z28=0),"ok 0",(J28/Z28-1)*100) -> 10.28524 | AN28: revision population+corrections mineures assiette
A29: Alimentation Humaine | B29: Assiette | C29: Sucres | D29: g éq. primaire/jour | E29: =SUMIFS(ADEME!$F:$F,ADEME!$A:$A,$A29,ADEME!$B:$B,$B29,ADEME!$C:$C,$C29,ADEME!$D:$D,$D29,ADEME!$E:$E,F$9) -> 90.871536 | F29: =SUMIFS(ADEME!$L:$L,ADEME!$A:$A,$A29,ADEME!$B:$B,$B29,ADEME!$C:$C,$C29,ADEME!$D:$D,$D29,ADEME!$E:$E,F$9) -> 78.180655 | G29: =SUMIFS(ADEME!$L:$L,ADEME!$A:$A,$A29,ADEME!$B:$B,$B29,ADEME!$C:$C,$C29,ADEME!$D:$D,$D29,ADEME!$E:$E,G$9) -> 81.653988 | H29: =SUMIFS(ADEME!$L:$L,ADEME!$A:$A,$A29,ADEME!$B:$B,$B29,ADEME!$C:$C,$C29,ADEME!$D:$D,$D29,ADEME!$E:$E,H$9) -> 83.203313 | I29: =SUMIFS(ADEME!$L:$L,ADEME!$A:$A,$A29,ADEME!$B:$B,$B29,ADEME!$C:$C,$C29,ADEME!$D:$D,$D29,ADEME!$E:$E,I$9) -> 84.446999 | J29: =SUMIFS(ADEME!$L:$L,ADEME!$A:$A,$A29,ADEME!$B:$B,$B29,ADEME!$C:$C,$C29,ADEME!$D:$D,$D29,ADEME!$E:$E,J$9) -> 91.541849 | L29: =A29&"-"&B29&"-"&C29 -> Alimentation Humaine-Assiette-Sucres | M29: =MATCH(L29,[6]RESULTATS_4!$W:$W,FALSE) -> 36 | N29: {=IFERROR(INDEX([6]RESULTATS_4!G:G,$M29),"-")} -> Alimentation Humaine | O29: {=IFERROR(INDEX([6]RESULTATS_4!H:H,$M29),"-")} -> Assiette | P29: {=IFERROR(INDEX([6]RESULTATS_4!I:I,$M29),"-")} -> Sucres | Q29: {=IFERROR(INDEX([6]RESULTATS_4!$J:$J,M29),"-")} -> g éq. primaire/jour | S29: =C29&"-"&D29 -> Sucres-g éq. primaire/jour | T29: =MATCH(S29,[2]S0!$R:$R,FALSE) -> 25 | U29: 115.99394 | V29: 97.744976 | W29: 95.480627 | X29: 110.7169 | Y29: 110.7169 | Z29: 118.95946 | AB29: 25 | AC29: 109.59931 | AD29: 25 | AE29: 109.59931 | AH29: =IF(AND(E29=0,U29=0),"ok 0",(E29/U29-1)*100) -> -21.658374 | AI29: =IF(AND(F29=0,V29=0),"ok 0",(F29/V29-1)*100) -> -20.015679 | AJ29: =IF(AND(G29=0,W29=0),"ok 0",(G29/W29-1)*100) -> -14.481093 | AK29: =IF(AND(H29=0,X29=0),"ok 0",(H29/X29-1)*100) -> -24.850393 | AL29: =IF(AND(I29=0,Y29=0),"ok 0",(I29/Y29-1)*100) -> -23.72709 | AM29: =IF(AND(J29=0,Z29=0),"ok 0",(J29/Z29-1)*100) -> -23.047861 | AN29: revision population+corrections mineures assiette
A30: Alimentation Humaine | B30: Assiette | C30: Légumineuses | D30: g éq. primaire/jour | E30: =SUMIFS(ADEME!$F:$F,ADEME!$A:$A,$A30,ADEME!$B:$B,$B30,ADEME!$C:$C,$C30,ADEME!$D:$D,$D30,ADEME!$E:$E,F$9) -> 7.0718332 | F30: =SUMIFS(ADEME!$L:$L,ADEME!$A:$A,$A30,ADEME!$B:$B,$B30,ADEME!$C:$C,$C30,ADEME!$D:$D,$D30,ADEME!$E:$E,F$9) -> 12.942792 | G30: =SUMIFS(ADEME!$L:$L,ADEME!$A:$A,$A30,ADEME!$B:$B,$B30,ADEME!$C:$C,$C30,ADEME!$D:$D,$D30,ADEME!$E:$E,G$9) -> 36.144255 | H30: =SUMIFS(ADEME!$L:$L,ADEME!$A:$A,$A30,ADEME!$B:$B,$B30,ADEME!$C:$C,$C30,ADEME!$D:$D,$D30,ADEME!$E:$E,H$9) -> 28.456051 | I30: =SUMIFS(ADEME!$L:$L,ADEME!$A:$A,$A30,ADEME!$B:$B,$B30,ADEME!$C:$C,$C30,ADEME!$D:$D,$D30,ADEME!$E:$E,I$9) -> 23.671142 | J30: =SUMIFS(ADEME!$L:$L,ADEME!$A:$A,$A30,ADEME!$B:$B,$B30,ADEME!$C:$C,$C30,ADEME!$D:$D,$D30,ADEME!$E:$E,J$9) -> 15.521163 | L30: =A30&"-"&B30&"-"&C30 -> Alimentation Humaine-Assiette-Légumineuses | M30: =MATCH(L30,[6]RESULTATS_4!$W:$W,FALSE) -> 31 | N30: {=IFERROR(INDEX([6]RESULTATS_4!G:G,$M30),"-")} -> Alimentation Humaine | O30: {=IFERROR(INDEX([6]RESULTATS_4!H:H,$M30),"-")} -> Assiette | P30: {=IFERROR(INDEX([6]RESULTATS_4!I:I,$M30),"-")} -> Légumineuses | Q30: {=IFERROR(INDEX([6]RESULTATS_4!$J:$J,M30),"-")} -> g éq. primaire/jour | S30: =C30&"-"&D30 -> Légumineuses-g éq. primaire/jour | T30: =MATCH(S30,[2]S0!$R:$R,FALSE) -> 26 | U30: 8.177047 | V30: 13.217718 | W30: 39.614303 | X30: 30.472541 | Y30: 24.378032 | Z30: 15.420671 | AB30: 26 | AC30: 32.231217 | AD30: 26 | AE30: 17.989516 | AH30: =IF(AND(E30=0,U30=0),"ok 0",(E30/U30-1)*100) -> -13.51605 | AI30: =IF(AND(F30=0,V30=0),"ok 0",(F30/V30-1)*100) -> -2.0799763 | AJ30: =IF(AND(G30=0,W30=0),"ok 0",(G30/W30-1)*100) -> -8.7595842 | AK30: =IF(AND(H30=0,X30=0),"ok 0",(H30/X30-1)*100) -> -6.6173989 | AL30: =IF(AND(I30=0,Y30=0),"ok 0",(I30/Y30-1)*100) -> -2.8997025 | AM30: =IF(AND(J30=0,Z30=0),"ok 0",(J30/Z30-1)*100) -> 0.65167123 | AN30: revision population+corrections mineures assiette
A31: Alimentation Humaine | B31: Assiette | C31: Fruits coque | D31: g éq. primaire/jour | E31: =SUMIFS(ADEME!$F:$F,ADEME!$A:$A,$A31,ADEME!$B:$B,$B31,ADEME!$C:$C,$C31,ADEME!$D:$D,$D31,ADEME!$E:$E,F$9) -> 25.368799 | F31: =SUMIFS(ADEME!$L:$L,ADEME!$A:$A,$A31,ADEME!$B:$B,$B31,ADEME!$C:$C,$C31,ADEME!$D:$D,$D31,ADEME!$E:$E,F$9) -> 42.130509 | G31: =SUMIFS(ADEME!$L:$L,ADEME!$A:$A,$A31,ADEME!$B:$B,$B31,ADEME!$C:$C,$C31,ADEME!$D:$D,$D31,ADEME!$E:$E,G$9) -> 24.626755 | H31: =SUMIFS(ADEME!$L:$L,ADEME!$A:$A,$A31,ADEME!$B:$B,$B31,ADEME!$C:$C,$C31,ADEME!$D:$D,$D31,ADEME!$E:$E,H$9) -> 21.890449 | I31: =SUMIFS(ADEME!$L:$L,ADEME!$A:$A,$A31,ADEME!$B:$B,$B31,ADEME!$C:$C,$C31,ADEME!$D:$D,$D31,ADEME!$E:$E,I$9) -> 19.154143 | J31: =SUMIFS(ADEME!$L:$L,ADEME!$A:$A,$A31,ADEME!$B:$B,$B31,ADEME!$C:$C,$C31,ADEME!$D:$D,$D31,ADEME!$E:$E,J$9) -> 18.055933 | L31: =A31&"-"&B31&"-"&C31 -> Alimentation Humaine-Assiette-Fruits coque | M31: =MATCH(L31,[6]RESULTATS_4!$W:$W,FALSE) -> 28 | N31: {=IFERROR(INDEX([6]RESULTATS_4!G:G,$M31),"-")} -> Alimentation Humaine | O31: {=IFERROR(INDEX([6]RESULTATS_4!H:H,$M31),"-")} -> Assiette | P31: {=IFERROR(INDEX([6]RESULTATS_4!I:I,$M31),"-")} -> Fruits coque | Q31: {=IFERROR(INDEX([6]RESULTATS_4!$J:$J,M31),"-")} -> g éq. primaire/jour | S31: =C31&"-"&D31 -> Fruits coque-g éq. primaire/jour | T31: =MATCH(S31,[2]S0!$R:$R,FALSE) -> 27 | U31: 12.280474 | V31: 15.420671 | W31: 9.1417622 | X31: 8.1260108 | Y31: 7.1102595 | Z31: 6.6088589 | AB31: 27 | AC31: 31.402596 | AD31: 27 | AE31: 20.725986 | AH31: =IF(AND(E31=0,U31=0),"ok 0",(E31/U31-1)*100) -> 106.57833 | AI31: =IF(AND(F31=0,V31=0),"ok 0",(F31/V31-1)*100) -> 173.20802 | AJ31: =IF(AND(G31=0,W31=0),"ok 0",(G31/W31-1)*100) -> 169.3874 | AK31: =IF(AND(H31=0,X31=0),"ok 0",(H31/X31-1)*100) -> 169.3874 | AL31: =IF(AND(I31=0,Y31=0),"ok 0",(I31/Y31-1)*100) -> 169.3874 | AM31: =IF(AND(J31=0,Z31=0),"ok 0",(J31/Z31-1)*100) -> 173.20802 | AN31: revision population+corrections mineures assiette
A32: Alimentation Humaine | B32: Assiette | C32: Plantes oléifères et huiles | D32: g éq. primaire/jour | E32: =SUMIFS(ADEME!$F:$F,ADEME!$A:$A,$A32,ADEME!$B:$B,$B32,ADEME!$C:$C,$C32,ADEME!$D:$D,$D32,ADEME!$E:$E,F$9) -> 77.743394 | F32: =SUMIFS(ADEME!$L:$L,ADEME!$A:$A,$A32,ADEME!$B:$B,$B32,ADEME!$C:$C,$C32,ADEME!$D:$D,$D32,ADEME!$E:$E,F$9) -> 88.38092 | G32: =SUMIFS(ADEME!$L:$L,ADEME!$A:$A,$A32,ADEME!$B:$B,$B32,ADEME!$C:$C,$C32,ADEME!$D:$D,$D32,ADEME!$E:$E,G$9) -> 149.69143 | H32: =SUMIFS(ADEME!$L:$L,ADEME!$A:$A,$A32,ADEME!$B:$B,$B32,ADEME!$C:$C,$C32,ADEME!$D:$D,$D32,ADEME!$E:$E,H$9) -> 116.66323 | I32: =SUMIFS(ADEME!$L:$L,ADEME!$A:$A,$A32,ADEME!$B:$B,$B32,ADEME!$C:$C,$C32,ADEME!$D:$D,$D32,ADEME!$E:$E,I$9) -> 101.00761 | J32: =SUMIFS(ADEME!$L:$L,ADEME!$A:$A,$A32,ADEME!$B:$B,$B32,ADEME!$C:$C,$C32,ADEME!$D:$D,$D32,ADEME!$E:$E,J$9) -> 97.584901 | L32: =A32&"-"&B32&"-"&C32 -> Alimentation Humaine-Assiette-Plantes oléifères et huiles | M32: =MATCH(L32,[6]RESULTATS_4!$W:$W,FALSE) -> 33 | N32: {=IFERROR(INDEX([6]RESULTATS_4!G:G,$M32),"-")} -> Alimentation Humaine | O32: {=IFERROR(INDEX([6]RESULTATS_4!H:H,$M32),"-")} -> Assiette | P32: {=IFERROR(INDEX([6]RESULTATS_4!I:I,$M32),"-")} -> Plantes oléifères et huiles | Q32: {=IFERROR(INDEX([6]RESULTATS_4!$J:$J,M32),"-")} -> g éq. primaire/jour | S32: =C32&"-"&D32 -> Plantes oléifères et huiles-g éq. primaire/jour | T32: =MATCH(S32,[2]S0!$R:$R,FALSE) -> 28 | U32: 60.140541 | V32: 90.687943 | W32: 112.24511 | X32: 94.925208 | Y32: 87.066095 | Z32: 83.115963 | AB32: 28 | AC32: 78.186222 | AD32: 28 | AE32: 78.186222 | AH32: =IF(AND(E32=0,U32=0),"ok 0",(E32/U32-1)*100) -> 29.269528 | AI32: =IF(AND(F32=0,V32=0),"ok 0",(F32/V32-1)*100) -> -2.543913 | AJ32: =IF(AND(G32=0,W32=0),"ok 0",(G32/W32-1)*100) -> 33.361201 | AK32: =IF(AND(H32=0,X32=0),"ok 0",(H32/X32-1)*100) -> 22.900156 | AL32: =IF(AND(I32=0,Y32=0),"ok 0",(I32/Y32-1)*100) -> 16.012567 | AM32: =IF(AND(J32=0,Z32=0),"ok 0",(J32/Z32-1)*100) -> 17.408134 | AN32: revision population+corrections mineures assiette
